Workbook

Sheet 表紙 
L2: 作成日 | O2: =変更履歴!C4 -> 45968
L3: 作成者 | O3: =変更履歴!D4 -> 郭 天心
L4: 最新更新日 | O4: {=LOOKUP(2,1/(変更履歴!C:C<>""),変更履歴!C:C)} -> 45975
L5: 最新更新者 | O5: {=LOOKUP(2,1/(変更履歴!D:D<>""),変更履歴!D:D)} -> 郭 天心
L6: 最新Ver. | O6: {=LOOKUP(2,1/(変更履歴!B:B<>""),変更履歴!B:B)} -> Ver2.0
A9: VWH切替設定手順
B19: Index
C21: 1 | D21: ='01_【VWH切替設定】フロー'!A3 -> 01_【VWH切替設定】フロー
C22: 2 | D22: ='02_手順'!A3 -> 02_手順
C23: =IF(D23="","",C22+1)
C24: =IF(D24="","",C23+1)
C25: =IF(D25="","",C24+1)
C26: =IF(D26="","",C25+1)
C27: =IF(D27="","",C26+1)
C28: =IF(D28="","",C27+1)
C29: =IF(D29="","",C28+1)
C30: =IF(D30="","",C29+1)
C31: =IF(D31="","",C30+1)
C32: =IF(D32="","",C31+1)
C33: =IF(D33="","",C32+1)
C34: =IF(D34="","",C33+1)

Sheet 変更履歴
B2: ＜ 変更履歴 ＞
B3: バージョン | C3: 変更日 | D3: 変更者 | E3: 変更シート | F3: 変更内容 | G3: 備考
B4: Ver1.0 | C4: 45968 | D4: 郭 天心 | E4: 01_フロー | F4: 新規
B5: Ver1.0 | C5: 45968 | D5: 郭 天心 | E5: 02_手順 | F5: 新規
B6: Ver2.0 | C6: 45974 | D6: 郭 天心 | E6: 01_フロー | F6: 対応フローの改修
B7: Ver2.0 | C7: 45975 | D7: 郭 天心 | E7: 02_手順 | F7: 詳細手順の改修

Sheet 00_リスト
B4: 対象／実施者ロール／承認要否／監査ログ
C7: 有無 | D7: 備考
B8: 実施対象者(役割) | D8: Power BI 作成者（VWH利用者）
B9: 申請・承認必要有無 | C9: 無
B10: 作業ログ・証跡有無 | C10: 無
B11: 失敗・誤設定時の影響範囲 | D11: 作業者本人のレポート更新が失敗する可能性があるが、他ユーザーや共有データへの影響はない
B12: ロールバック方法 | C12: 有 | D12: 事前に手動バックアップしたファイルを、安全なフォルダーから元の場所へ上書き戻すことでロールバック可能 ※バックアップの方法は「2-1) VWH 新規セットアップ」の手順6に記載しています

Sheet 01_【VWH切替設定】フロー
A1: 1
A3: {=MID(CELL("filename",A1),FIND("]",CELL("filename",A1))+1,50)} -> 01_【VWH切替設定】フロー
A7: 前提
B8: 開発環境への接続に使用するアカウント情報が準備されていること。
B9: Power BI Desktop がインストール済みで、開発用レポートの編集・発行権限を有していること。
A13: 対応フロー
C16: フロー

Sheet 02_手順
A3: {=MID(CELL("filename",A1),FIND("]",CELL("filename",A1))+1,10)} -> 02_手順
A7: 前提
B8: 開発環境への接続に使用するアカウント情報が準備されていること。
B9: Power BI Desktop がインストール済みで、開発用レポートの編集・発行権限を有していること。
A13: 手順一覧
B15: No | D15: 手順 | M15: 概要
B16: 1 | D16: 事前確認 | M16: 既存ユーザーが自身の接続方式を確認します。
B17: 2-1 | D17: VWH 新規セットアップ | M17: PowerBIの設定ファイルを編集する手順を示します。
B18: 2-2 | D18: VWH 切替作業 | M18: Azure CLIのインストール手順を示します。
A23: 詳細手順
B25: 1) 事前確認
C27: No | F27: 手順 | S27: 詳細 | CA27: 証跡
C28: 1
F29: ※本ステップは、既存ユーザーが自身の接続方式を確認するためのステップです。
G30: 新規ユーザーの場合は、確認作業は不要のため、直接 「2-1 VWH 新規セットアップ」 を参照してください。
C32: 2 | F32: ・VWH 切替の前に、現在の接続方式が Datahub 経由かどうかを確認します。
F33: 下記の方法で判断できます。
G35: Power BI Desktop を開き、現在のデータ接続先を確認します。
G37: 1. 上部メニューの 「ホーム」 をクリック
G39: 2. 「データの変換」 の下向き小矢印をクリック
G41: 3. 表示されるメニューから 「データ ソース設定」 を選択します
G43: これにより、レポートがどのサーバー／コネクションを使用しているかを確認できます。
C55: 3 | F55: ・「データ ソース設定」画面に表示される Impala の接続先を確認します。
F56: もし、データソースの接続先に 以下の文字列が含まれている場合、
F57: 現在は Datahub 接続方式を使用している と判断できます
F58: その場合は、【2-2) VWH 切替作業】 に進んでください。
F59: ”cdp-dap-kudu-ve-je-master10.toyotecd.kj09-szpi.a0.cloudera.site:443”
F61: 上記以外の場合は、【2-1) VWH 新規セットアップ】に進んでください。
B75: 2-1) VWH 新規セットアップ
C77: No | F77: 手順 | S77: 詳細 | CA77: 証跡
C78: 1 | F78: ・Cloudera 公式サイトから Impala ODBC Connector 2.7.0
F79: をダウンロードし、インストールします。
F81: 公式ダウンロードURL：
G82: https://www.cloudera.com/downloads/connectors/impala/odbc/2-7-0.html
F85: バージョン：
G86: Impala ODBC Connector2.7.0
F88: Operating System：
G89: Windows
F90: ※ 本手順では Windows 版のみ を対象として説明します。
F92: OS Version：
...

Sheet 03_別紙_セキュリティキー
A1: 1
A3: {=MID(CELL("filename",A1),FIND("]",CELL("filename",A1))+1,2)} -> 03 | D3: VWH切替&開発環境接続手順
A7: 前提
B8: 開発環境への接続に使用する認証スクリプトおよびアカウント情報が準備されていること
B9: Power BI Desktop がインストール済みで、開発用レポートの編集・発行権限を有していること。
B10: VWHに接続するための権限付与が済んでいること
E17: ODBC Driver設定内容：
E18: [Simba Impala ODBC Driver]
E19: # Oringinally PowerBI will use its embedded driver, we can change it to Cloudera version
E20: # Driver=Simba Impala ODBC Driver\ImpalaODBC_sb64.dll
E21: Driver=Cloudera ODBC Driver for Impala\lib\ClouderaImpalaODBC64.dll
E22: cloudera.impalaodbc.ini設定内容：
E23: [Driver]
E24: SSL=1
E25: TransportMode=http
E26: HTTPPath=cliservice
E27: AuthMech=3
E28: HTTPAuthCookies=impala.auth,JSESSIONID,KNOXSESSIONID,impala.session.id
... E33: サブスクリプション
E34: 1 | F34: 開発 | R34: dev-toyotecdap
E35: 2 | F35: 本番 | R35: toyotecdap
E36: 3 | F36: 検証 | R36: ve-toyotecdap
E37: Impaサーバー
E38: impala-proxy-toyotecdap-vwh-pr-default.dw-toyotecdap-env.kj09-szpi.cloudera.site:443
